[2025-08-24 11:08:12 +0900] [82237] [INFO] Starting gunicorn 20.1.0
[2025-08-24 11:08:12 +0900] [82237] [INFO] Listening at: http://0.0.0.0:8000 (82237)
[2025-08-24 11:08:12 +0900] [82237] [INFO] Using worker: threads
[2025-08-24 11:08:12 +0900] [82238] [INFO] Booting worker with pid: 82238
[2025-08-24 11:08:12 +0900] [82239] [INFO] Booting worker with pid: 82239
[2025-08-24 11:08:12 +0900] [82238] [ERROR] Exception in worker process
Traceback (most recent call last):
  File "/home/pi/plant_dashboard/.venv/lib/python3.11/site-packages/gunicorn/arbiter.py", line 589, in spawn_worker
    worker.init_process()
  File "/home/pi/plant_dashboard/.venv/lib/python3.11/site-packages/gunicorn/workers/gthread.py", line 92, in init_process
    super().init_process()
  File "/home/pi/plant_dashboard/.venv/lib/python3.11/site-packages/gunicorn/workers/base.py", line 134, in init_process
    self.load_wsgi()
  File "/home/pi/plant_dashboard/.venv/lib/python3.11/site-packages/gunicorn/workers/base.py", line 146, in load_wsgi
    self.wsgi = self.app.wsgi()
                ^^^^^^^^^^^^^^^
  File "/home/pi/plant_dashboard/.venv/lib/python3.11/site-packages/gunicorn/app/base.py", line 67, in wsgi
    self.callable = self.load()
                    ^^^^^^^^^^^
  File "/home/pi/plant_dashboard/.venv/lib/python3.11/site-packages/gunicorn/app/wsgiapp.py", line 58, in load
    return self.load_wsgiapp()
           ^^^^^^^^^^^^^^^^^^^
  File "/home/pi/plant_dashboard/.venv/lib/python3.11/site-packages/gunicorn/app/wsgiapp.py", line 48, in load_wsgiapp
    return util.import_app(self.app_uri)
           ^^^^^^^^^^^^^^^^^^^^^^^^^^^^^
  File "/home/pi/plant_dashboard/.venv/lib/python3.11/site-packages/gunicorn/util.py", line 359, in import_app
    mod = importlib.import_module(module)
          ^^^^^^^^^^^^^^^^^^^^^^^^^^^^^^^
  File "/usr/lib/python3.11/importlib/__init__.py", line 126, in import_module
    return _bootstrap._gcd_import(name[level:], package, level)
           ^^^^^^^^^^^^^^^^^^^^^^^^^^^^^^^^^^^^^^^^^^^^^^^^^^^^
  File "<frozen importlib._bootstrap>", line 1206, in _gcd_import
  File "<frozen importlib._bootstrap>", line 1178, in _find_and_load
  File "<frozen importlib._bootstrap>", line 1149, in _find_and_load_unlocked
  File "<frozen importlib._bootstrap>", line 690, in _load_unlocked
  File "<frozen importlib._bootstrap_external>", line 940, in exec_module
  File "<frozen importlib._bootstrap>", line 241, in _call_with_frames_removed
  File "/home/pi/plant_dashboard/app.py", line 11, in <module>
    from flask import Flask, Response, render_template, jsonify, request
  File "/home/pi/plant_dashboard/.venv/lib/python3.11/site-packages/flask/__init__.py", line 5, in <module>
    from .app import Flask as Flask
  File "/home/pi/plant_dashboard/.venv/lib/python3.11/site-packages/flask/app.py", line 30, in <module>
    from werkzeug.urls import url_quote
ImportError: cannot import name 'url_quote' from 'werkzeug.urls' (/home/pi/plant_dashboard/.venv/lib/python3.11/site-packages/werkzeug/urls.py)
[2025-08-24 11:08:12 +0900] [82238] [INFO] Worker exiting (pid: 82238)
[2025-08-24 11:08:12 +0900] [82239] [ERROR] Exception in worker process
Traceback (most recent call last):
  File "/home/pi/plant_dashboard/.venv/lib/python3.11/site-packages/gunicorn/arbiter.py", line 589, in spawn_worker
    worker.init_process()
  File "/home/pi/plant_dashboard/.venv/lib/python3.11/site-packages/gunicorn/workers/gthread.py", line 92, in init_process
    super().init_process()
  File "/home/pi/plant_dashboard/.venv/lib/python3.11/site-packages/gunicorn/workers/base.py", line 134, in init_process
    self.load_wsgi()
  File "/home/pi/plant_dashboard/.venv/lib/python3.11/site-packages/gunicorn/workers/base.py", line 146, in load_wsgi
    self.wsgi = self.app.wsgi()
                ^^^^^^^^^^^^^^^
  File "/home/pi/plant_dashboard/.venv/lib/python3.11/site-packages/gunicorn/app/base.py", line 67, in wsgi
    self.callable = self.load()
                    ^^^^^^^^^^^
  File "/home/pi/plant_dashboard/.venv/lib/python3.11/site-packages/gunicorn/app/wsgiapp.py", line 58, in load
    return self.load_wsgiapp()
           ^^^^^^^^^^^^^^^^^^^
  File "/home/pi/plant_dashboard/.venv/lib/python3.11/site-packages/gunicorn/app/wsgiapp.py", line 48, in load_wsgiapp
    return util.import_app(self.app_uri)
           ^^^^^^^^^^^^^^^^^^^^^^^^^^^^^
  File "/home/pi/plant_dashboard/.venv/lib/python3.11/site-packages/gunicorn/util.py", line 359, in import_app
    mod = importlib.import_module(module)
          ^^^^^^^^^^^^^^^^^^^^^^^^^^^^^^^
  File "/usr/lib/python3.11/importlib/__init__.py", line 126, in import_module
    return _bootstrap._gcd_import(name[level:], package, level)
           ^^^^^^^^^^^^^^^^^^^^^^^^^^^^^^^^^^^^^^^^^^^^^^^^^^^^
  File "<frozen importlib._bootstrap>", line 1206, in _gcd_import
  File "<frozen importlib._bootstrap>", line 1178, in _find_and_load
  File "<frozen importlib._bootstrap>", line 1149, in _find_and_load_unlocked
  File "<frozen importlib._bootstrap>", line 690, in _load_unlocked
  File "<frozen importlib._bootstrap_external>", line 940, in exec_module
  File "<frozen importlib._bootstrap>", line 241, in _call_with_frames_removed
  File "/home/pi/plant_dashboard/app.py", line 11, in <module>
    from flask import Flask, Response, render_template, jsonify, request
  File "/home/pi/plant_dashboard/.venv/lib/python3.11/site-packages/flask/__init__.py", line 5, in <module>
    from .app import Flask as Flask
  File "/home/pi/plant_dashboard/.venv/lib/python3.11/site-packages/flask/app.py", line 30, in <module>
    from werkzeug.urls import url_quote
ImportError: cannot import name 'url_quote' from 'werkzeug.urls' (/home/pi/plant_dashboard/.venv/lib/python3.11/site-packages/werkzeug/urls.py)
[2025-08-24 11:08:12 +0900] [82239] [INFO] Worker exiting (pid: 82239)
[2025-08-24 11:08:12 +0900] [82237] [WARNING] Worker with pid 82239 was terminated due to signal 15
[2025-08-24 11:08:13 +0900] [82237] [INFO] Shutting down: Master
[2025-08-24 11:08:13 +0900] [82237] [INFO] Reason: Worker failed to boot.
[2025-08-27 00:52:42 +0900] [1904] [INFO] Starting gunicorn 20.1.0
[2025-08-27 00:52:42 +0900] [1904] [INFO] Listening at: http://0.0.0.0:8000 (1904)
[2025-08-27 00:52:42 +0900] [1904] [INFO] Using worker: threads
[2025-08-27 00:52:42 +0900] [1905] [INFO] Booting worker with pid: 1905
[2025-08-27 00:52:42 +0900] [1905] [ERROR] Exception in worker process
Traceback (most recent call last):
  File "/home/pi/plant_dashboard/.venv/lib/python3.11/site-packages/gunicorn/arbiter.py", line 589, in spawn_worker
    worker.init_process()
  File "/home/pi/plant_dashboard/.venv/lib/python3.11/site-packages/gunicorn/workers/gthread.py", line 92, in init_process
    super().init_process()
  File "/home/pi/plant_dashboard/.venv/lib/python3.11/site-packages/gunicorn/workers/base.py", line 134, in init_process
    self.load_wsgi()
  File "/home/pi/plant_dashboard/.venv/lib/python3.11/site-packages/gunicorn/workers/base.py", line 146, in load_wsgi
    self.wsgi = self.app.wsgi()
                ^^^^^^^^^^^^^^^
  File "/home/pi/plant_dashboard/.venv/lib/python3.11/site-packages/gunicorn/app/base.py", line 67, in wsgi
    self.callable = self.load()
                    ^^^^^^^^^^^
  File "/home/pi/plant_dashboard/.venv/lib/python3.11/site-packages/gunicorn/app/wsgiapp.py", line 58, in load
    return self.load_wsgiapp()
           ^^^^^^^^^^^^^^^^^^^
  File "/home/pi/plant_dashboard/.venv/lib/python3.11/site-packages/gunicorn/app/wsgiapp.py", line 48, in load_wsgiapp
    return util.import_app(self.app_uri)
           ^^^^^^^^^^^^^^^^^^^^^^^^^^^^^
  File "/home/pi/plant_dashboard/.venv/lib/python3.11/site-packages/gunicorn/util.py", line 359, in import_app
    mod = importlib.import_module(module)
          ^^^^^^^^^^^^^^^^^^^^^^^^^^^^^^^
  File "/usr/lib/python3.11/importlib/__init__.py", line 126, in import_module
    return _bootstrap._gcd_import(name[level:], package, level)
           ^^^^^^^^^^^^^^^^^^^^^^^^^^^^^^^^^^^^^^^^^^^^^^^^^^^^
  File "<frozen importlib._bootstrap>", line 1206, in _gcd_import
  File "<frozen importlib._bootstrap>", line 1178, in _find_and_load
  File "<frozen importlib._bootstrap>", line 1149, in _find_and_load_unlocked
  File "<frozen importlib._bootstrap>", line 690, in _load_unlocked
  File "<frozen importlib._bootstrap_external>", line 940, in exec_module
  File "<frozen importlib._bootstrap>", line 241, in _call_with_frames_removed
  File "/home/pi/plant_dashboard/wsgi.py", line 4, in <module>
    from app import app
ImportError: cannot import name 'app' from 'app' (/home/pi/plant_dashboard/app.py)
[2025-08-27 00:52:42 +0900] [1905] [INFO] Worker exiting (pid: 1905)
[2025-08-27 00:52:42 +0900] [1904] [INFO] Shutting down: Master
[2025-08-27 00:52:42 +0900] [1904] [INFO] Reason: Worker failed to boot.
